<mujoco model="navigation">
  
  <size njmax="3000" nconmax="1500"/>
  <option integrator="RK4" timestep="0.01"/>

  <worldbody>
    <light cutoff="100" diffuse="1 1 1" dir="-0 0 -1.3" directional="true" exponent="1" pos="0 0 1.3" specular=".1 .1 .1"/>
    <geom conaffinity="1" condim="3" name="floor" pos="0 0 0" rgba="0.8 0.9 0.8 1" size="5 5 5" type="plane" material="MatPlane"/>
    <body name="dog" pos="0 0 0">
      <site name="dog" pos="0 0 -.25"/>
      <camera name="camera" mode="trackcom" pos="0 -3. 1.5." xyaxes="1 0 0 0 0.5 1"/>
      <joint axis="1 0 0" limited="false" name="axisx" pos="0 0 0" type="slide"/>
      <joint axis="0 1 0" limited="false" name="axisy" pos="0 0 0" type="slide"/>
      <joint axis="0 0 1" limited="false" name="rootz" pos="0 0 0" type="hinge"/>
      <joint axis="0 0 1" limited="false" name="axisz" pos="0 0 0" type="slide"/>
      <geom mass="8." size="0.25 0.25 " name="dog" type="cylinder" rgba="0.8 0.4 0. 1" friction="1 0.005 0.0001" />
    </body>

    <body name="wall_0" pos="-5.25 0. 0.5">
      <geom mass="1000." size="0.25 5. 0.5" name="wall_0" type="box" rgba="0. 0. 0.8 1"/>
    </body>
    <body name="wall_1" pos="5.25 0. 0.5">
      <geom mass="1000." size="0.25 5. 0.5" name="wall_1" type="box" rgba="0. 0. 0.8 1"/>
    </body>
    <body name="wall_2" pos="0. -5.25 0.5">
      <geom mass="1000." size="5. 0.25 0.5" name="wall_2" type="box" rgba="0. 0. 0.8 1"/>
    </body>
    <body name="wall_3" pos="0. 5.25 0.5">
      <geom mass="1000." size="5. 0.25 0.5" name="wall_3" type="box" rgba="0. 0. 0.8 1"/>
    </body>

    <body name="obs_00" pos="0. 0. 0.5">
      <joint axis="1 0 0" limited="false" name="axisx_00" pos="0 0 0" type="slide"/>
      <joint axis="0 1 0" limited="false" name="axisy_00" pos="0 0 0" type="slide"/>
      <geom mass="1000." size="0.25 0.25 0.5" name="obs_00" type="box" rgba="0. 0. 0.8 1"/>
    </body>
    <body name="obs_01" pos="0. 0. 0.5">
      <joint axis="1 0 0" limited="false" name="axisx_01" pos="0 0 0" type="slide"/>
      <joint axis="0 1 0" limited="false" name="axisy_01" pos="0 0 0" type="slide"/>
      <geom mass="1000." size="0.25 0.25 0.5" name="obs_01" type="box" rgba="0. 0. 0.8 1"/>
    </body>
    <body name="obs_02" pos="0. 0. 0.5">
      <joint axis="1 0 0" limited="false" name="axisx_02" pos="0 0 0" type="slide"/>
      <joint axis="0 1 0" limited="false" name="axisy_02" pos="0 0 0" type="slide"/>
      <geom mass="1000." size="0.25 0.25 0.5" name="obs_02" type="box" rgba="0. 0. 0.8 1"/>
    </body>
    <body name="obs_03" pos="0. 0. 0.5">
      <joint axis="1 0 0" limited="false" name="axisx_03" pos="0 0 0" type="slide"/>
      <joint axis="0 1 0" limited="false" name="axisy_03" pos="0 0 0" type="slide"/>
      <geom mass="1000." size="0.25 0.25 0.5" name="obs_03" type="box" rgba="0. 0. 0.8 1"/>
    </body>
    <body name="obs_04" pos="0. 0. 0.5">
      <joint axis="1 0 0" limited="false" name="axisx_04" pos="0 0 0" type="slide"/>
      <joint axis="0 1 0" limited="false" name="axisy_04" pos="0 0 0" type="slide"/>
      <geom mass="1000." size="0.25 0.25 0.5" name="obs_04" type="box" rgba="0. 0. 0.8 1"/>
    </body>
    <body name="obs_05" pos="0. 0. 0.5">
      <joint axis="1 0 0" limited="false" name="axisx_05" pos="0 0 0" type="slide"/>
      <joint axis="0 1 0" limited="false" name="axisy_05" pos="0 0 0" type="slide"/>
      <geom mass="1000." size="0.25 0.25 0.5" name="obs_05" type="box" rgba="0. 0. 0.8 1"/>
    </body>
    <body name="obs_06" pos="0. 0. 0.5">
      <joint axis="1 0 0" limited="false" name="axisx_06" pos="0 0 0" type="slide"/>
      <joint axis="0 1 0" limited="false" name="axisy_06" pos="0 0 0" type="slide"/>
      <geom mass="1000." size="0.25 0.25 0.5" name="obs_06" type="box" rgba="0. 0. 0.8 1"/>
    </body>
    <body name="obs_07" pos="0. 0. 0.5">
      <joint axis="1 0 0" limited="false" name="axisx_07" pos="0 0 0" type="slide"/>
      <joint axis="0 1 0" limited="false" name="axisy_07" pos="0 0 0" type="slide"/>
      <geom mass="1000." size="0.25 0.25 0.5" name="obs_07" type="box" rgba="0. 0. 0.8 1"/>
    </body>
    <body name="obs_08" pos="0. 0. 0.5">
      <joint axis="1 0 0" limited="false" name="axisx_08" pos="0 0 0" type="slide"/>
      <joint axis="0 1 0" limited="false" name="axisy_08" pos="0 0 0" type="slide"/>
      <geom mass="1000." size="0.25 0.25 0.5" name="obs_08" type="box" rgba="0. 0. 0.8 1"/>
    </body>
    <body name="obs_09" pos="0. 0. 0.5">
      <joint axis="1 0 0" limited="false" name="axisx_09" pos="0 0 0" type="slide"/>
      <joint axis="0 1 0" limited="false" name="axisy_09" pos="0 0 0" type="slide"/>
      <geom mass="1000." size="0.25 0.25 0.5" name="obs_09" type="box" rgba="0. 0. 0.8 1"/>
    </body>
    <body name="obs_10" pos="0. 0. 0.5">
      <joint axis="1 0 0" limited="false" name="axisx_10" pos="0 0 0" type="slide"/>
      <joint axis="0 1 0" limited="false" name="axisy_10" pos="0 0 0" type="slide"/>
      <geom mass="1000." size="0.25 0.25 0.5" name="obs_10" type="box" rgba="0. 0. 0.8 1"/>
    </body>
    <body name="obs_11" pos="0. 0. 0.5">
      <joint axis="1 0 0" limited="false" name="axisx_11" pos="0 0 0" type="slide"/>
      <joint axis="0 1 0" limited="false" name="axisy_11" pos="0 0 0" type="slide"/>
      <geom mass="1000." size="0.25 0.25 0.5" name="obs_11" type="box" rgba="0. 0. 0.8 1"/>
    </body>
    <body name="obs_12" pos="0. 0. 0.5">
      <joint axis="1 0 0" limited="false" name="axisx_12" pos="0 0 0" type="slide"/>
      <joint axis="0 1 0" limited="false" name="axisy_12" pos="0 0 0" type="slide"/>
      <geom mass="1000." size="0.25 0.25 0.5" name="obs_12" type="box" rgba="0. 0. 0.8 1"/>
    </body>
    <body name="obs_13" pos="0. 0. 0.5">
      <joint axis="1 0 0" limited="false" name="axisx_13" pos="0 0 0" type="slide"/>
      <joint axis="0 1 0" limited="false" name="axisy_13" pos="0 0 0" type="slide"/>
      <geom mass="1000." size="0.25 0.25 0.5" name="obs_13" type="box" rgba="0. 0. 0.8 1"/>
    </body>
    <body name="obs_14" pos="0. 0. 0.5">
      <joint axis="1 0 0" limited="false" name="axisx_14" pos="0 0 0" type="slide"/>
      <joint axis="0 1 0" limited="false" name="axisy_14" pos="0 0 0" type="slide"/>
      <geom mass="1000." size="0.25 0.25 0.5" name="obs_14" type="box" rgba="0. 0. 0.8 1"/>
    </body>
    <body name="obs_15" pos="0. 0. 0.5">
      <joint axis="1 0 0" limited="false" name="axisx_15" pos="0 0 0" type="slide"/>
      <joint axis="0 1 0" limited="false" name="axisy_15" pos="0 0 0" type="slide"/>
      <geom mass="1000." size="0.25 0.25 0.5" name="obs_15" type="box" rgba="0. 0. 0.8 1"/>
    </body>
    <body name="obs_16" pos="0. 0. 0.5">
      <joint axis="1 0 0" limited="false" name="axisx_16" pos="0 0 0" type="slide"/>
      <joint axis="0 1 0" limited="false" name="axisy_16" pos="0 0 0" type="slide"/>
      <geom mass="1000." size="0.25 0.25 0.5" name="obs_16" type="box" rgba="0. 0. 0.8 1"/>
    </body>
    <body name="obs_17" pos="0. 0. 0.5">
      <joint axis="1 0 0" limited="false" name="axisx_17" pos="0 0 0" type="slide"/>
      <joint axis="0 1 0" limited="false" name="axisy_17" pos="0 0 0" type="slide"/>
      <geom mass="1000." size="0.25 0.25 0.5" name="obs_17" type="box" rgba="0. 0. 0.8 1"/>
    </body>
    <body name="obs_18" pos="0. 0. 0.5">
      <joint axis="1 0 0" limited="false" name="axisx_18" pos="0 0 0" type="slide"/>
      <joint axis="0 1 0" limited="false" name="axisy_18" pos="0 0 0" type="slide"/>
      <geom mass="1000." size="0.25 0.25 0.5" name="obs_18" type="box" rgba="0. 0. 0.8 1"/>
    </body>
    <body name="obs_19" pos="0. 0. 0.5">
      <joint axis="1 0 0" limited="false" name="axisx_19" pos="0 0 0" type="slide"/>
      <joint axis="0 1 0" limited="false" name="axisy_19" pos="0 0 0" type="slide"/>
      <geom mass="1000." size="0.25 0.25 0.5" name="obs_19" type="box" rgba="0. 0. 0.8 1"/>
    </body>

    <body name="destination" pos="0 0 0">
      <site name="destination" pos="0 0 0"/>
      <joint axis="1 0 0" limited="false" name="destinationx" pos="0 0 0" type="slide"/>
      <joint axis="0 1 0" limited="false" name="destinationy" pos="0 0 0" type="slide"/>
      <geom name="destination" pos="0 0 0" size="0.01 0.01 0.01" type="box"/>
    </body>

  </worldbody>

  <tendon>
    <spatial width="0.03" rgba=".95 .0 .0 1" limited="true" range="0 100."> 
      <site site="dog"/>
      <site site="destination"/>
    </spatial>
  </tendon>

  <actuator>
    <motor ctrllimited="true" ctrlrange="-100.0 100.0" joint="axisx"/>
    <motor ctrllimited="true" ctrlrange="-100.0 100.0" joint="axisy"/>
    <motor ctrllimited="true" ctrlrange="-100.0 100.0" joint="rootz"/>
  </actuator>

  <asset>
    <texture type="skybox" builtin="gradient" rgb1=".4 .5 .6" rgb2="0 0 0" width="100" height="100"/>
    <texture builtin="flat" height="1278" mark="cross" markrgb="1 1 1" name="texgeom" random="0.01" rgb1="0.8 0.6 0.4" rgb2="0.8 0.6 0.4" type="cube" width="127"/>
    <texture builtin="checker" height="100" name="texplane" rgb1="0 0 0" rgb2="0.8 0.8 0.8" type="2d" width="100"/>
    <material name="MatPlane" reflectance="0.5" shininess="1" specular="1" texrepeat="5 5" texture="texplane"/>
    <material name="geom" texture="texgeom" texuniform="true"/>
  </asset>

</mujoco>