<mujoco model="navigation">
  
  <option integrator="RK4" timestep="0.01"/>

  <worldbody>
    <light cutoff="100" diffuse="1 1 1" dir="-0 0 -1.3" directional="true" exponent="1" pos="0 0 1.3" specular=".1 .1 .1"/>
    <geom conaffinity="1" condim="3" name="floor" pos="0 0 0" rgba="0.8 0.9 0.8 1" size="40 40 40" type="plane" material="MatPlane"/>
    <body name="dog" pos="0. 0. .6">
      <camera name="camera" mode="trackcom" pos="0 -3. 1.5." xyaxes="1 0 0 0 0.5 1"/>
      <joint axis="1 0 0" limited="false" name="axisx" pos="0 0 0" type="slide"/>
      <joint axis="0 1 0" limited="false" name="axisy" pos="0 0 0" type="slide"/>
      <joint axis="0 0 1" limited="false" name="rootz" pos="0 0 0" type="hinge"/>
      <joint axis="0 0 1" limited="false" name="axisz" pos="0 0 0" type="slide"/>
      <geom mass="1." size="0.6 0.6 0.6" name="dog" type="box" friction="0.01 0.005 0.0001" />
    </body>
  </worldbody>

  <actuator>
    <motor ctrllimited="true" ctrlrange="-100.0 100.0" joint="axisx"/>
    <motor ctrllimited="true" ctrlrange="-100.0 100.0" joint="axisy"/>
    <motor ctrllimited="true" ctrlrange="-100.0 100.0" joint="rootz"/>
  </actuator>

  <asset>
    <texture type="skybox" builtin="gradient" rgb1=".4 .5 .6" rgb2="0 0 0" width="100" height="100"/>
    <texture builtin="flat" height="1278" mark="cross" markrgb="1 1 1" name="texgeom" random="0.01" rgb1="0.8 0.6 0.4" rgb2="0.8 0.6 0.4" type="cube" width="127"/>
    <texture builtin="checker" height="100" name="texplane" rgb1="0 0 0" rgb2="0.8 0.8 0.8" type="2d" width="100"/>
    <material name="MatPlane" reflectance="0.5" shininess="1" specular="1" texrepeat="60 60" texture="texplane"/>
    <material name="geom" texture="texgeom" texuniform="true"/>
  </asset>

</mujoco>